<?xml version="1.0" ?>
<robot name="mycobot" xmlns:xacro="http://www.ros.org/wiki/xacro">

<xacro:include filename="$(find mycobot_description)/urdf/materials.xacro"/>
<link name="base_link">
  <visual>
    <origin xyz="0 0 0" rpy="0 0 0"/>
    <geometry>
      <mesh filename="file://$(find mycobot_description)/meshes/base_link.stl" scale="0.001 0.001 0.001"/>
    </geometry>
    <material name="silver"/>
  </visual>
  <collision>
    <origin xyz="0 0 0" rpy="0 0 0"/>
    <geometry>
      <mesh filename="file://$(find mycobot_description)/meshes/base_link.stl" scale="0.001 0.001 0.001"/>
    </geometry>
  </collision>
</link>

<link name="link1">
  <visual>
    <origin xyz="0.0 -0.060072 -0.114761" rpy="0 0 0"/>
    <geometry>
      <mesh filename="file://$(find mycobot_description)/meshes/link1.stl" scale="0.001 0.001 0.001"/>
    </geometry>
    <material name="silver"/>
  </visual>
  <collision>
    <origin xyz="0.0 -0.060072 -0.114761" rpy="0 0 0"/>
    <geometry>
      <mesh filename="file://$(find mycobot_description)/meshes/link1.stl" scale="0.001 0.001 0.001"/>
    </geometry>
  </collision>
</link>

<link name="link2">
  <visual>
    <origin xyz="-0.045 -0.060072 -0.199761" rpy="0 0 0"/>
    <geometry>
      <mesh filename="file://$(find mycobot_description)/meshes/link2.stl" scale="0.001 0.001 0.001"/>
    </geometry>
    <material name="silver"/>
  </visual>
  <collision>
    <origin xyz="-0.045 -0.060072 -0.199761" rpy="0 0 0"/>
    <geometry>
      <mesh filename="file://$(find mycobot_description)/meshes/link2.stl" scale="0.001 0.001 0.001"/>
    </geometry>
  </collision>
</link>

<link name="link3">
  <visual>
    <origin xyz="-0.045 -0.060072 -0.335761" rpy="0 0 0"/>
    <geometry>
      <mesh filename="file://$(find mycobot_description)/meshes/link3.stl" scale="0.001 0.001 0.001"/>
    </geometry>
    <material name="silver"/>
  </visual>
  <collision>
    <origin xyz="-0.045 -0.060072 -0.335761" rpy="0 0 0"/>
    <geometry>
      <mesh filename="file://$(find mycobot_description)/meshes/link3.stl" scale="0.001 0.001 0.001"/>
    </geometry>
  </collision>
</link>

<link name="link4">
  <visual>
    <origin xyz="-0.045 -0.060072 -0.434761" rpy="0 0 0"/>
    <geometry>
      <mesh filename="file://$(find mycobot_description)/meshes/link4.stl" scale="0.001 0.001 0.001"/>
    </geometry>
    <material name="silver"/>
  </visual>
  <collision>
    <origin xyz="-0.045 -0.060072 -0.434761" rpy="0 0 0"/>
    <geometry>
      <mesh filename="file://$(find mycobot_description)/meshes/link4.stl" scale="0.001 0.001 0.001"/>
    </geometry>
  </collision>
</link>

<link name="link5">
  <visual>
    <origin xyz="-0.09 -0.060072 -0.479761" rpy="0 0 0"/>
    <geometry>
      <mesh filename="file://$(find mycobot_description)/meshes/link5.stl" scale="0.001 0.001 0.001"/>
    </geometry>
    <material name="silver"/>
  </visual>
  <collision>
    <origin xyz="-0.09 -0.060072 -0.479761" rpy="0 0 0"/>
    <geometry>
      <mesh filename="file://$(find mycobot_description)/meshes/link5.stl" scale="0.001 0.001 0.001"/>
    </geometry>
  </collision>
</link>

<link name="link6">
  <visual>
    <origin xyz="-0.13 -0.060072 -0.529761" rpy="0 0 0"/>
    <geometry>
      <mesh filename="file://$(find mycobot_description)/meshes/link6.stl" scale="0.001 0.001 0.001"/>
    </geometry>
    <material name="silver"/>
  </visual>
  <collision>
    <origin xyz="-0.13 -0.060072 -0.529761" rpy="0 0 0"/>
    <geometry>
      <mesh filename="file://$(find mycobot_description)/meshes/link6.stl" scale="0.001 0.001 0.001"/>
    </geometry>
  </collision>
</link>

<link name="gripper_left1">
  <visual>
    <origin xyz="-0.261438 -0.008607 -0.536903" rpy="0 0 0"/>
    <geometry>
      <mesh filename="file://$(find mycobot_description)/meshes/gripper_left1.stl" scale="0.001 0.001 0.001"/>
    </geometry>
    <material name="silver"/>
  </visual>
  <collision>
    <origin xyz="-0.261438 -0.008607 -0.536903" rpy="0 0 0"/>
    <geometry>
      <mesh filename="file://$(find mycobot_description)/meshes/gripper_left1.stl" scale="0.001 0.001 0.001"/>
    </geometry>
  </collision>
</link>

<link name="gripper_right1">
  <visual>
    <origin xyz="-0.261438 -0.111297 -0.533501" rpy="0 0 0"/>
    <geometry>
      <mesh filename="file://$(find mycobot_description)/meshes/gripper_right1.stl" scale="0.001 0.001 0.001"/>
    </geometry>
    <material name="silver"/>
  </visual>
  <collision>
    <origin xyz="-0.261438 -0.111297 -0.533501" rpy="0 0 0"/>
    <geometry>
      <mesh filename="file://$(find mycobot_description)/meshes/gripper_right1.stl" scale="0.001 0.001 0.001"/>
    </geometry>
  </collision>
</link>

<link name="gripper_left3">
  <visual>
    <origin xyz="-0.21039 -0.041612 -0.533403" rpy="0 0 0"/>
    <geometry>
      <mesh filename="file://$(find mycobot_description)/meshes/gripper_left3.stl" scale="0.001 0.001 0.001"/>
    </geometry>
    <material name="silver"/>
  </visual>
  <collision>
    <origin xyz="-0.21039 -0.041612 -0.533403" rpy="0 0 0"/>
    <geometry>
      <mesh filename="file://$(find mycobot_description)/meshes/gripper_left3.stl" scale="0.001 0.001 0.001"/>
    </geometry>
  </collision>
</link>

<link name="gripper_right3">
  <visual>
    <origin xyz="-0.21039 -0.078292 -0.533403" rpy="0 0 0"/>
    <geometry>
      <mesh filename="file://$(find mycobot_description)/meshes/gripper_right3.stl" scale="0.001 0.001 0.001"/>
    </geometry>
    <material name="silver"/>
  </visual>
  <collision>
    <origin xyz="-0.21039 -0.078292 -0.533403" rpy="0 0 0"/>
    <geometry>
      <mesh filename="file://$(find mycobot_description)/meshes/gripper_right3.stl" scale="0.001 0.001 0.001"/>
    </geometry>
  </collision>
</link>

<!-- <link name="gripper_right2">
  <inertial>
    <origin xyz="0.029939990495379626 0.020889826569869555 -0.00039518056690335257" rpy="0 0 0"/>
    <mass value="0.05227728599311408"/>
    <inertia ixx="6e-06" iyy="1.6e-05" izz="2e-05" ixy="-8e-06" iyz="-1e-06" ixz="-1e-06"/>
  </inertial>
  <visual>
    <origin xyz="-0.188075 -0.104364 -0.526413" rpy="0 0 0"/>
    <geometry>
      <mesh filename="file://$(find mycobot_description)/meshes/gripper_right2.stl" scale="0.001 0.001 0.001"/>
    </geometry>
    <material name="silver"/>
  </visual>
  <collision>
    <origin xyz="-0.188075 -0.104364 -0.526413" rpy="0 0 0"/>
    <geometry>
      <mesh filename="file://$(find mycobot_description)/meshes/gripper_right2.stl" scale="0.001 0.001 0.001"/>
    </geometry>
  </collision>
</link> -->

<!-- <link name="gripper_left2">
  <inertial>
    <origin xyz="0.03183851476317609 -0.022109126086089934 0.0008827048100953361" rpy="0 0 0"/>
    <mass value="0.05612369952823833"/>
    <inertia ixx="6e-06" iyy="1.7e-05" izz="2.1e-05" ixy="8e-06" iyz="1e-06" ixz="-2e-06"/>
  </inertial>
  <visual>
    <origin xyz="-0.188075 -0.01558 -0.525913" rpy="0 0 0"/>
    <geometry>
      <mesh filename="file://$(find mycobot_description)/meshes/gripper_left2.stl" scale="0.001 0.001 0.001"/>
    </geometry>
    <material name="silver"/>
  </visual>
  <collision>
    <origin xyz="-0.188075 -0.01558 -0.525913" rpy="0 0 0"/>
    <geometry>
      <mesh filename="file://$(find mycobot_description)/meshes/gripper_left2.stl" scale="0.001 0.001 0.001"/>
    </geometry>
  </collision>
</link> -->

<link name="gripper_base">
  <visual>
    <origin xyz="-0.15 -0.060072 -0.529761" rpy="0 0 0"/>
    <geometry>
      <mesh filename="file://$(find mycobot_description)/meshes/gripper_base.stl" scale="0.001 0.001 0.001"/>
    </geometry>
    <material name="silver"/>
  </visual>
  <collision>
    <origin xyz="-0.15 -0.060072 -0.529761" rpy="0 0 0"/>
    <geometry>
      <mesh filename="file://$(find mycobot_description)/meshes/gripper_base.stl" scale="0.001 0.001 0.001"/>
    </geometry>
  </collision>
</link>

<!-- joint -->
<joint name="joint2_to_joint1" type="revolute">
  <origin xyz="0.0 0.060072 0.114761" rpy="0 0 0"/>
  <parent link="base_link"/>
  <child link="link1"/>
  <axis xyz="-0.0 0.0 1.0"/>
  <limit upper="2.87" lower="-2.87" effort="100" velocity="100"/>
</joint>

<joint name="joint3_to_joint2" type="revolute">
  <origin xyz="0.045 0.0 0.085" rpy="0 0 0"/>
  <parent link="link1"/>
  <child link="link2"/>
  <axis xyz="1.0 -0.0 0.0"/>
  <limit upper="2.87" lower="-2.87" effort="100" velocity="100"/>
</joint>

<joint name="joint4_to_joint3" type="revolute">
  <origin xyz="0.0 0.0 0.136" rpy="0 0 0"/>
  <parent link="link2"/>
  <child link="link3"/>
  <axis xyz="-1.0 0.0 -0.0"/>
  <limit upper="2.87" lower="-2.87" effort="100" velocity="100"/>
</joint>

<joint name="joint5_to_joint4" type="revolute">
  <origin xyz="0.0 0.0 0.099" rpy="0 0 0"/>
  <parent link="link3"/>
  <child link="link4"/>
  <axis xyz="1.0 0.0 0.0"/>
  <limit upper="2.87" lower="-2.87" effort="100" velocity="100"/>
</joint>

<joint name="joint6_to_joint5" type="revolute">
  <origin xyz="0.045 0.0 0.045" rpy="0 0 0"/>
  <parent link="link4"/>
  <child link="link5"/>
  <axis xyz="0.0 0.0 1.0"/>
  <limit upper="2.87" lower="-2.87" effort="100" velocity="100"/>
</joint>

<joint name="joint6output_to_joint6" type="revolute">
  <origin xyz="0.04 0.0 0.05" rpy="0 0 0"/>
  <parent link="link5"/>
  <child link="link6"/>
  <axis xyz="1.0 -0.0 0.0"/>
  <limit upper="2.87" lower="-2.87" effort="100" velocity="100"/>
</joint>

<!-- gripper joint -->

<joint name="joint6output_to_gripper_base" type="fixed">
  <origin xyz="0.02 0.0 0.0" rpy="0 0 0"/>
  <parent link="link6"/>
  <child link="gripper_base"/>
</joint>

<joint name="gripper_controller" type="revolute">
  <origin xyz="0.06039 0.01822 0.003642" rpy="0 0 -0.42"/>
  <parent link="gripper_base"/>
  <child link="gripper_right3"/>
  <axis xyz="0.0 -0.0 -1.0"/>
  <limit upper="0.3" lower="-0.7" effort="100" velocity="100"/>
</joint>

<joint name="gripper_right3_to_gripper_right1" type="revolute">
  <origin xyz="0.051048 0.033005 9.8e-05" rpy="0 0 0.42"/>
  <parent link="gripper_right3"/>
  <child link="gripper_right1"/>
  <axis xyz="-0.0 -0.0 -1.0"/>
  <limit upper="0.0" lower="-0.698132" effort="100" velocity="100"/>
  <mimic joint="gripper_controller" multiplier="-1" offset="0"/>
</joint>

<!-- <joint name="gripper_base_to_gripper_right2" type="revolute">
  <origin xyz="0.038075 0.044292 -0.003348" rpy="0 0 0"/>
  <parent link="gripper_base"/>
  <child link="gripper_right2"/>
  <axis xyz="0.0 -0.0 -1.0"/>
  <limit upper="0.698132" lower="0.0" effort="100" velocity="100"/>
  <mimic joint="gripper_controller" multiplier="1" offset="0"/>
</joint> -->

<joint name="gripper_left3_to_gripper_left1" type="revolute">
  <origin xyz="0.051048 -0.033005 0.0035" rpy="0 0 -0.42"/>
  <parent link="gripper_left3"/>
  <child link="gripper_left1"/>
  <axis xyz="0.0 0.0 1.0"/>
  <limit upper="0.0" lower="-0.698132" effort="100" velocity="100"/>
  <mimic joint="gripper_controller" multiplier="-1" offset="0"/>
</joint>

<joint name="gripper_base_to_gripper_left3" type="revolute">
  <origin xyz="0.06039 -0.01846 0.003642" rpy="0 0 0.42"/>
  <parent link="gripper_base"/>
  <child link="gripper_left3"/>
  <axis xyz="0.0 -0.0 -1.0"/>
  <limit upper="0.0" lower="-0.698132" effort="100" velocity="100"/>
  <mimic joint="gripper_controller" multiplier="-1" offset="0"/>
</joint>

<!-- <joint name="gripper_base_to_gripper_left2" type="revolute">
  <origin xyz="0.038075 -0.044492 -0.003848" rpy="0 0 0"/>
  <parent link="gripper_base"/>
  <child link="gripper_left2"/>
  <axis xyz="-0.0 0.0 1.0"/>
  <limit upper="0.698132" lower="0.0" effort="100" velocity="100"/>
  <mimic joint="gripper_controller" multiplier="1" offset="0"/>
</joint> -->

</robot>
