<?xml version="1.0" ?>
<robot name="moiro_arm" xmlns:xacro="http://www.ros.org/wiki/xacro">

<xacro:include filename="$(find moiro_arm_description)/urdf/materials.xacro" />
<link name="link0">
  <inertial>
    <origin xyz="-2.1294138884612695e-08 -0.012465741614897647 0.043604773377263574" rpy="0 0 0"/>
    <mass value="9.352590646947165"/>
    <inertia ixx="0.020014" iyy="0.013492" izz="0.021572" ixy="-0.0" iyz="-0.000111" ixz="-0.0"/>
  </inertial>
  <visual>
    <origin xyz="0 0 0" rpy="0 0 0"/>
    <geometry>
      <mesh filename="file://$(find moiro_arm_description)/meshes/link0.stl" scale="0.001 0.001 0.001"/>
    </geometry>
    <material name="silver"/>
  </visual>
  <collision>
    <origin xyz="0 0 0" rpy="0 0 0"/>
    <geometry>
      <mesh filename="file://$(find moiro_arm_description)/meshes/link0.stl" scale="0.001 0.001 0.001"/>
    </geometry>
  </collision>
</link>

<link name="link1">
  <inertial>
    <origin xyz="0.006896766224728663 1.0277085082508868e-17 0.055490186869056435" rpy="0 0 0"/>
    <mass value="3.4735206294395446"/>
    <inertia ixx="0.004461" iyy="0.004757" izz="0.002424" ixy="0.0" iyz="0.0" ixz="-0.000777"/>
  </inertial>
  <visual>
    <origin xyz="0.0 -0.0 -0.09" rpy="0 0 0"/>
    <geometry>
      <mesh filename="file://$(find moiro_arm_description)/meshes/link1.stl" scale="0.001 0.001 0.001"/>
    </geometry>
    <material name="silver"/>
  </visual>
  <collision>
    <origin xyz="0.0 -0.0 -0.09" rpy="0 0 0"/>
    <geometry>
      <mesh filename="file://$(find moiro_arm_description)/meshes/link1.stl" scale="0.001 0.001 0.001"/>
    </geometry>
  </collision>
</link>

<link name="link2">
  <inertial>
    <origin xyz="0.036906585755669324 -5.127617707147077e-18 0.06800000000000106" rpy="0 0 0"/>
    <mass value="5.91988968680626"/>
    <inertia ixx="0.0188" iyy="0.019335" izz="0.004161" ixy="-0.0" iyz="0.0" ixz="0.0"/>
  </inertial>
  <visual>
    <origin xyz="-0.045 -0.0 -0.175" rpy="0 0 0"/>
    <geometry>
      <mesh filename="file://$(find moiro_arm_description)/meshes/link2.stl" scale="0.001 0.001 0.001"/>
    </geometry>
    <material name="silver"/>
  </visual>
  <collision>
    <origin xyz="-0.045 -0.0 -0.175" rpy="0 0 0"/>
    <geometry>
      <mesh filename="file://$(find moiro_arm_description)/meshes/link2.stl" scale="0.001 0.001 0.001"/>
    </geometry>
  </collision>
</link>

<link name="link3">
  <inertial>
    <origin xyz="-0.03502268825299596 3.6027099078187094e-15 0.04950000000000104" rpy="0 0 0"/>
    <mass value="4.802107093668197"/>
    <inertia ixx="0.01014" iyy="0.010584" izz="0.003386" ixy="-0.0" iyz="-0.0" ixz="0.0"/>
  </inertial>
  <visual>
    <origin xyz="-0.045 0.0 -0.311" rpy="0 0 0"/>
    <geometry>
      <mesh filename="file://$(find moiro_arm_description)/meshes/link3.stl" scale="0.001 0.001 0.001"/>
    </geometry>
    <material name="silver"/>
  </visual>
  <collision>
    <origin xyz="-0.045 0.0 -0.311" rpy="0 0 0"/>
    <geometry>
      <mesh filename="file://$(find moiro_arm_description)/meshes/link3.stl" scale="0.001 0.001 0.001"/>
    </geometry>
  </collision>
</link>

<link name="link4">
  <inertial>
    <origin xyz="0.034423872869188424 7.388104622801813e-15 0.010576127130808965" rpy="0 0 0"/>
    <mass value="2.265107015236222"/>
    <inertia ixx="0.001595" iyy="0.001803" izz="0.001595" ixy="-0.0" iyz="-0.0" ixz="-0.000324"/>
  </inertial>
  <visual>
    <origin xyz="-0.045 -0.0 -0.41" rpy="0 0 0"/>
    <geometry>
      <mesh filename="file://$(find moiro_arm_description)/meshes/link4.stl" scale="0.001 0.001 0.001"/>
    </geometry>
    <material name="silver"/>
  </visual>
  <collision>
    <origin xyz="-0.045 -0.0 -0.41" rpy="0 0 0"/>
    <geometry>
      <mesh filename="file://$(find moiro_arm_description)/meshes/link4.stl" scale="0.001 0.001 0.001"/>
    </geometry>
  </collision>
</link>

<link name="link5">
  <inertial>
    <origin xyz="-3.816391647148976e-15 8.447372615657932e-15 0.04211669650613492" rpy="0 0 0"/>
    <mass value="3.029827579494103"/>
    <inertia ixx="0.0025" iyy="0.002976" izz="0.002441" ixy="-0.0" iyz="-0.0" ixz="-0.0"/>
  </inertial>
  <visual>
    <origin xyz="-0.09 -0.0 -0.455" rpy="0 0 0"/>
    <geometry>
      <mesh filename="file://$(find moiro_arm_description)/meshes/link5.stl" scale="0.001 0.001 0.001"/>
    </geometry>
    <material name="silver"/>
  </visual>
  <collision>
    <origin xyz="-0.09 -0.0 -0.455" rpy="0 0 0"/>
    <geometry>
      <mesh filename="file://$(find moiro_arm_description)/meshes/link5.stl" scale="0.001 0.001 0.001"/>
    </geometry>
  </collision>
</link>

<link name="link6">
  <inertial>
    <origin xyz="0.00999999999999615 8.43769498715119e-15 3.3306690738754696e-16" rpy="0 0 0"/>
    <mass value="0.6042068071016569"/>
    <inertia ixx="0.00037" iyy="0.000205" izz="0.000205" ixy="-0.0" iyz="0.0" ixz="0.0"/>
  </inertial>
  <visual>
    <origin xyz="-0.13 -0.0 -0.505" rpy="0 0 0"/>
    <geometry>
      <mesh filename="file://$(find moiro_arm_description)/meshes/link6.stl" scale="0.001 0.001 0.001"/>
    </geometry>
    <material name="silver"/>
  </visual>
  <collision>
    <origin xyz="-0.13 -0.0 -0.505" rpy="0 0 0"/>
    <geometry>
      <mesh filename="file://$(find moiro_arm_description)/meshes/link6.stl" scale="0.001 0.001 0.001"/>
    </geometry>
  </collision>
</link>

<link name="cobot_camera">
  <inertial>
    <origin xyz="0.017423960091247193 0.0032534266311959052 0.0058193857187291975" rpy="0 0 0"/>
    <mass value="0.21027144182469326"/>
    <inertia ixx="0.000387" iyy="0.000194" izz="0.000246" ixy="-5e-06" iyz="2e-06" ixz="1.9e-05"/>
  </inertial>
  <visual>
    <origin xyz="-0.15 -0.0 -0.505" rpy="0 0 0"/>
    <geometry>
      <mesh filename="file://$(find moiro_arm_description)/meshes/cobot_camera.stl" scale="0.001 0.001 0.001"/>
    </geometry>
    <material name="silver"/>
  </visual>
  <collision>
    <origin xyz="-0.15 -0.0 -0.505" rpy="0 0 0"/>
    <geometry>
      <mesh filename="file://$(find moiro_arm_description)/meshes/cobot_camera.stl" scale="0.001 0.001 0.001"/>
    </geometry>
  </collision>
</link>

<joint name="mycobot_joint_1" type="revolute">
  <origin xyz="0.0 0.0 0.09" rpy="0 0 0"/>
  <parent link="link0"/>
  <child link="link1"/>
  <axis xyz="-0.0 -0.0 1.0"/>
  <limit upper="2.792527" lower="-2.792527" effort="100" velocity="100"/>
</joint>

<joint name="mycobot_joint_2" type="revolute">
  <origin xyz="0.045 0.0 0.085" rpy="0 0 0"/>
  <parent link="link1"/>
  <child link="link2"/>
  <axis xyz="1.0 0.0 0.0"/>
  <limit upper="2.792527" lower="-2.792527" effort="100" velocity="100"/>
</joint>

<joint name="mycobot_joint_3" type="revolute">
  <origin xyz="0.0 -0.0 0.136" rpy="0 0 0"/>
  <parent link="link2"/>
  <child link="link3"/>
  <axis xyz="-1.0 -0.0 -0.0"/>
  <limit upper="2.792527" lower="-2.792527" effort="100" velocity="100"/>
</joint>

<joint name="mycobot_joint_4" type="revolute">
  <origin xyz="0.0 0.0 0.099" rpy="0 0 0"/>
  <parent link="link3"/>
  <child link="link4"/>
  <axis xyz="1.0 -0.0 0.0"/>
  <limit upper="2.792527" lower="-2.792527" effort="100" velocity="100"/>
</joint>

<joint name="mycobot_joint_5" type="revolute">
  <origin xyz="0.045 0.0 0.045" rpy="0 0 0"/>
  <parent link="link4"/>
  <child link="link5"/>
  <axis xyz="0.0 0.0 1.0"/>
  <limit upper="2.792527" lower="-2.792527" effort="100" velocity="100"/>
</joint>

<joint name="mycobot_joint_6" type="revolute">
  <origin xyz="0.04 0.0 0.05" rpy="0 0 0"/>
  <parent link="link5"/>
  <child link="link6"/>
  <axis xyz="1.0 -0.0 0.0"/>
  <limit upper="2.792527" lower="-2.792527" effort="100" velocity="100"/>
</joint>

<joint name="cobot_camera_joint" type="fixed">
  <origin xyz="0.02 0.0 0.0" rpy="0 0 0"/>
  <parent link="link6"/>
  <child link="cobot_camera"/>
</joint>

</robot>
